2023-03-13 14:46:10,032 ERROR: Exception on / [GET] [in D:\!Student\microblog\venv\lib\site-packages\flask\app.py:1744]
Traceback (most recent call last):
  File "D:\!Student\microblog\venv\lib\site-packages\sqlalchemy\engine\base.py", line 1964, in _exec_single_context
    self.dialect.do_execute(
  File "D:\!Student\microblog\venv\lib\site-packages\sqlalchemy\engine\default.py", line 748, in do_execute
    cursor.execute(statement, parameters)
sqlite3.OperationalError: no such table: user

The above exception was the direct cause of the following exception:

Traceback (most recent call last):
  File "D:\!Student\microblog\venv\lib\site-packages\flask\app.py", line 2528, in wsgi_app
    response = self.full_dispatch_request()
  File "D:\!Student\microblog\venv\lib\site-packages\flask\app.py", line 1825, in full_dispatch_request
    rv = self.handle_user_exception(e)
  File "D:\!Student\microblog\venv\lib\site-packages\flask\app.py", line 1821, in full_dispatch_request
    rv = self.preprocess_request()
  File "D:\!Student\microblog\venv\lib\site-packages\flask\app.py", line 2312, in preprocess_request
    rv = self.ensure_sync(before_func)()
  File "D:\!Student\microblog\project\routes.py", line 12, in before_request
    if current_user.is_authenticated:
  File "D:\!Student\microblog\venv\lib\site-packages\werkzeug\local.py", line 316, in __get__
    obj = instance._get_current_object()
  File "D:\!Student\microblog\venv\lib\site-packages\werkzeug\local.py", line 520, in _get_current_object
    return get_name(local())  # type: ignore
  File "D:\!Student\microblog\venv\lib\site-packages\flask_login\utils.py", line 25, in <lambda>
    current_user = LocalProxy(lambda: _get_user())
  File "D:\!Student\microblog\venv\lib\site-packages\flask_login\utils.py", line 372, in _get_user
    current_app.login_manager._load_user()
  File "D:\!Student\microblog\venv\lib\site-packages\flask_login\login_manager.py", line 364, in _load_user
    user = self._user_callback(user_id)
  File "D:\!Student\microblog\project\models.py", line 65, in load_user
    return User.query.get(int(id))
  File "<string>", line 2, in get
  File "D:\!Student\microblog\venv\lib\site-packages\sqlalchemy\util\deprecations.py", line 383, in warned
    return fn(*args, **kwargs)  # type: ignore[no-any-return]
  File "D:\!Student\microblog\venv\lib\site-packages\sqlalchemy\orm\query.py", line 1130, in get
    return self._get_impl(ident, loading.load_on_pk_identity)
  File "D:\!Student\microblog\venv\lib\site-packages\sqlalchemy\orm\query.py", line 1139, in _get_impl
    return self.session._get_impl(
  File "D:\!Student\microblog\venv\lib\site-packages\sqlalchemy\orm\session.py", line 3672, in _get_impl
    return db_load_fn(
  File "D:\!Student\microblog\venv\lib\site-packages\sqlalchemy\orm\loading.py", line 668, in load_on_pk_identity
    session.execute(
  File "D:\!Student\microblog\venv\lib\site-packages\sqlalchemy\orm\session.py", line 2229, in execute
    return self._execute_internal(
  File "D:\!Student\microblog\venv\lib\site-packages\sqlalchemy\orm\session.py", line 2124, in _execute_internal
    result: Result[Any] = compile_state_cls.orm_execute_statement(
  File "D:\!Student\microblog\venv\lib\site-packages\sqlalchemy\orm\context.py", line 253, in orm_execute_statement
    result = conn.execute(
  File "D:\!Student\microblog\venv\lib\site-packages\sqlalchemy\engine\base.py", line 1414, in execute
    return meth(
  File "D:\!Student\microblog\venv\lib\site-packages\sqlalchemy\sql\elements.py", line 486, in _execute_on_connection
    return connection._execute_clauseelement(
  File "D:\!Student\microblog\venv\lib\site-packages\sqlalchemy\engine\base.py", line 1638, in _execute_clauseelement
    ret = self._execute_context(
  File "D:\!Student\microblog\venv\lib\site-packages\sqlalchemy\engine\base.py", line 1842, in _execute_context
    return self._exec_single_context(
  File "D:\!Student\microblog\venv\lib\site-packages\sqlalchemy\engine\base.py", line 1983, in _exec_single_context
    self._handle_dbapi_exception(
  File "D:\!Student\microblog\venv\lib\site-packages\sqlalchemy\engine\base.py", line 2326, in _handle_dbapi_exception
    raise sqlalchemy_exception.with_traceback(exc_info[2]) from e
  File "D:\!Student\microblog\venv\lib\site-packages\sqlalchemy\engine\base.py", line 1964, in _exec_single_context
    self.dialect.do_execute(
  File "D:\!Student\microblog\venv\lib\site-packages\sqlalchemy\engine\default.py", line 748, in do_execute
    cursor.execute(statement, parameters)
sqlalchemy.exc.OperationalError: (sqlite3.OperationalError) no such table: user
[SQL: SELECT user.id AS user_id, user.username AS user_username, user.email AS user_email, user.password_hash AS user_password_hash, user.about_me AS user_about_me, user.last_seen AS user_last_seen 
FROM user 
WHERE user.id = ?]
[parameters: (3,)]
(Background on this error at: https://sqlalche.me/e/20/e3q8)
2023-03-13 14:46:10,443 ERROR: Exception on /favicon.ico [GET] [in D:\!Student\microblog\venv\lib\site-packages\flask\app.py:1744]
Traceback (most recent call last):
  File "D:\!Student\microblog\venv\lib\site-packages\sqlalchemy\engine\base.py", line 1964, in _exec_single_context
    self.dialect.do_execute(
  File "D:\!Student\microblog\venv\lib\site-packages\sqlalchemy\engine\default.py", line 748, in do_execute
    cursor.execute(statement, parameters)
sqlite3.OperationalError: no such table: user

The above exception was the direct cause of the following exception:

Traceback (most recent call last):
  File "D:\!Student\microblog\venv\lib\site-packages\flask\app.py", line 2528, in wsgi_app
    response = self.full_dispatch_request()
  File "D:\!Student\microblog\venv\lib\site-packages\flask\app.py", line 1825, in full_dispatch_request
    rv = self.handle_user_exception(e)
  File "D:\!Student\microblog\venv\lib\site-packages\flask\app.py", line 1821, in full_dispatch_request
    rv = self.preprocess_request()
  File "D:\!Student\microblog\venv\lib\site-packages\flask\app.py", line 2312, in preprocess_request
    rv = self.ensure_sync(before_func)()
  File "D:\!Student\microblog\project\routes.py", line 12, in before_request
    if current_user.is_authenticated:
  File "D:\!Student\microblog\venv\lib\site-packages\werkzeug\local.py", line 316, in __get__
    obj = instance._get_current_object()
  File "D:\!Student\microblog\venv\lib\site-packages\werkzeug\local.py", line 520, in _get_current_object
    return get_name(local())  # type: ignore
  File "D:\!Student\microblog\venv\lib\site-packages\flask_login\utils.py", line 25, in <lambda>
    current_user = LocalProxy(lambda: _get_user())
  File "D:\!Student\microblog\venv\lib\site-packages\flask_login\utils.py", line 372, in _get_user
    current_app.login_manager._load_user()
  File "D:\!Student\microblog\venv\lib\site-packages\flask_login\login_manager.py", line 364, in _load_user
    user = self._user_callback(user_id)
  File "D:\!Student\microblog\project\models.py", line 65, in load_user
    return User.query.get(int(id))
  File "<string>", line 2, in get
  File "D:\!Student\microblog\venv\lib\site-packages\sqlalchemy\util\deprecations.py", line 383, in warned
    return fn(*args, **kwargs)  # type: ignore[no-any-return]
  File "D:\!Student\microblog\venv\lib\site-packages\sqlalchemy\orm\query.py", line 1130, in get
    return self._get_impl(ident, loading.load_on_pk_identity)
  File "D:\!Student\microblog\venv\lib\site-packages\sqlalchemy\orm\query.py", line 1139, in _get_impl
    return self.session._get_impl(
  File "D:\!Student\microblog\venv\lib\site-packages\sqlalchemy\orm\session.py", line 3672, in _get_impl
    return db_load_fn(
  File "D:\!Student\microblog\venv\lib\site-packages\sqlalchemy\orm\loading.py", line 668, in load_on_pk_identity
    session.execute(
  File "D:\!Student\microblog\venv\lib\site-packages\sqlalchemy\orm\session.py", line 2229, in execute
    return self._execute_internal(
  File "D:\!Student\microblog\venv\lib\site-packages\sqlalchemy\orm\session.py", line 2124, in _execute_internal
    result: Result[Any] = compile_state_cls.orm_execute_statement(
  File "D:\!Student\microblog\venv\lib\site-packages\sqlalchemy\orm\context.py", line 253, in orm_execute_statement
    result = conn.execute(
  File "D:\!Student\microblog\venv\lib\site-packages\sqlalchemy\engine\base.py", line 1414, in execute
    return meth(
  File "D:\!Student\microblog\venv\lib\site-packages\sqlalchemy\sql\elements.py", line 486, in _execute_on_connection
    return connection._execute_clauseelement(
  File "D:\!Student\microblog\venv\lib\site-packages\sqlalchemy\engine\base.py", line 1638, in _execute_clauseelement
    ret = self._execute_context(
  File "D:\!Student\microblog\venv\lib\site-packages\sqlalchemy\engine\base.py", line 1842, in _execute_context
    return self._exec_single_context(
  File "D:\!Student\microblog\venv\lib\site-packages\sqlalchemy\engine\base.py", line 1983, in _exec_single_context
    self._handle_dbapi_exception(
  File "D:\!Student\microblog\venv\lib\site-packages\sqlalchemy\engine\base.py", line 2326, in _handle_dbapi_exception
    raise sqlalchemy_exception.with_traceback(exc_info[2]) from e
  File "D:\!Student\microblog\venv\lib\site-packages\sqlalchemy\engine\base.py", line 1964, in _exec_single_context
    self.dialect.do_execute(
  File "D:\!Student\microblog\venv\lib\site-packages\sqlalchemy\engine\default.py", line 748, in do_execute
    cursor.execute(statement, parameters)
sqlalchemy.exc.OperationalError: (sqlite3.OperationalError) no such table: user
[SQL: SELECT user.id AS user_id, user.username AS user_username, user.email AS user_email, user.password_hash AS user_password_hash, user.about_me AS user_about_me, user.last_seen AS user_last_seen 
FROM user 
WHERE user.id = ?]
[parameters: (3,)]
(Background on this error at: https://sqlalche.me/e/20/e3q8)
